Move prover returns: exiting with verification errors
error: abort not covered by any of the `aborts_if` clauses
   ┌─ tests/sources/functional/script_incorrect.move:12:5
   │
12 │ ╭     spec main {
13 │ │         aborts_if false;
14 │ │     }
   │ ╰─────^
   │
   ┌─ tests/sources/functional/script_provider.move:10:9
   │
10 │         move_to(account, Info<T>{})
   │         --------------------------- abort happened here with execution failure
   │
   =     at tests/sources/functional/script_incorrect.move:6: main
   =         account = <redacted>
   =     at tests/sources/functional/script_incorrect.move:8: main
   =     at tests/sources/functional/script_incorrect.move:10: main
   =     at tests/sources/functional/script_provider.move:8: register
   =         account = <redacted>
   =     at tests/sources/functional/script_provider.move:9: register
   =     at ../move-stdlib/sources/signer.move:12: address_of
   =         s = <redacted>
   =     at ../move-stdlib/sources/signer.move:13: address_of
   =         result = <redacted>
   =     at ../move-stdlib/sources/signer.move:14: address_of
   =     at tests/sources/functional/script_provider.move:10: register
   =         <redacted> = <redacted>
   =     at tests/sources/functional/script_provider.move:10: register
   =         ABORTED
